Workbook

Sheet Truncated VRC01
A1: VRC01 Light Chain | B1: VRC01 Light Chain (PROC) | C1: ∆∆G (Kcal/mol) | E1: VRC01 Heavy Chain | F1: VRC01 Heavy Chain | G1: ∆∆G (Kcal/mol) | J1: 5 ns - Heavy Chain | AA1: 20 ns - Heavy Chain | AV1: 100 ns - Heavy Chain
A2: Q27 | B2: 549 | C2: -0.24 | E2: I30 | F2: 328 | G2: -0.01 | J2: Time | K2: Chain | L2: Residue Number | M2: Mutation | N2: Alanine | O2: DG-Complex | P2: Uncertainty-Complex | Q2: DG-Antibody | R2: Uncertainty-Antibody | S2: DDG | T2: Uncertainty | U2: Uncertainty^2 | V2: Database | W2: Squared Error | X2: Convergence Status | AA2: Time | AB2: Chain | AC2: Residue Number | AD2: Mutation | AE2: Alanine | AF2: DG-Complex | AG2: Uncertainty-Complex | AH2: DG-Antibody | AI2: Uncertainty-Antibody | AJ2: DDG | AK2: Uncertainty | AL2: Uncertainty^2 | AM2: Database | AN2: Squared Error | AO2: Convergence Status | AV2: Time | AW2: Chain | AX2: Residue Number | AY2: Mutation | AZ2: Alanine | BA2: DG-Complex | BB2: Uncertainty-Complex | BC2: DG-Antibody | BD2: Uncertainty-Antibody | BE2: DDG | BF2: Uncertainty | BG2: Uncertainty^2 | BH2: Database | BI2: Squared Error | BJ2: Convergence Status
A3: Y28 | B3: 550 | C3: 0.97 | E3: T33 | F3: 331 | G3: 0.7 | J3: 5 ns | K3: Heavy Chain | L3: I30 | M3: I328 | N3: A328 | O3: -13.536 | P3: 0.457 | Q3: -13.862 | R3: 0.163 | S3: =O3-Q3 -> 0.326 | T3: =SQRT((P3)^2 + (R3)^2) -> 0.48519893 | U3: =T3^2 -> 0.235418 | V3: -0.01 | W3: =(S3-V3)^2 -> 0.112896 | X3: Converged | AA3: 20 ns | AB3: Heavy Chain | AC3: I30 | AD3: I328 | AE3: A328 | AF3: -12.409 | AG3: 0.209 | AH3: -13.033 | AI3: 0.202 | AJ3: =AF3-AH3 -> 0.624 | AK3: =SQRT((AG3)^2 + (AI3)^2) -> 0.29066304 | AL3: =AK3^2 -> 0.084485 | AM3: -0.01 | AN3: =(AJ3-AM3)^2 -> 0.401956 | AO3: Both Sides Convered after 1st 20 ns | AV3: 100 ns | AW3: Heavy Chain | AX3: I30 | AY3: I328 | AZ3: A328 | BA3: -12.769 | BB3: 0.187 | BC3: -13.163 | BD3: 0.079 | BE3: =BA3-BC3 -> 0.394 | BF3: =SQRT((BB3)^2 + (BD3)^2) -> 0.20300246 | BG3: =BF3^2 -> 0.04121 | BH3: -0.01 | BI3: =(BE3-BH3)^2 -> 0.163216 | BJ3: Both Sides Convered after 1st 100 ns
A4: S30 | B4: 552 | C4: -0.15 | E4: W47 | F4: 345 | G4: 1.19 | J4: 5 ns | K4: Heavy Chain | L4: T33 | M4: T331 | N4: A331 | O4: 11.72 | P4: 0.115 | Q4: 11.284 | R4: 0.14 | S4: =O4-Q4 -> 0.436 | T4: =SQRT((P4)^2 + (R4)^2) -> 0.18117671 | U4: =T4^2 -> 0.032825 | V4: 0.7 | W4: =(S4-V4)^2 -> 0.069696 | X4: Converged | AA4: 20 ns | AB4: Heavy Chain | AC4: T33 | AD4: T331 | AE4: A331 | AF4: 11.23 | AG4: 0.182 | AH4: 11.393 | AI4: 0.092 | AJ4: =AF4-AH4 -> -0.163 | AK4: =SQRT((AG4)^2 + (AI4)^2) -> 0.20393136 | AL4: =AK4^2 -> 0.041588 | AM4: 0.7 | AN4: =(AJ4-AM4)^2 -> 0.744769 | AO4: Both Sides Convered after 1st 20 ns | AV4: 100 ns | AW4: Heavy Chain | AX4: T33 | AY4: T331 | AZ4: A331 | BA4: 11.429 | BB4: 0.177 | BC4: 10.743 | BD4: 0.136 | BE4: =BA4-BC4 -> 0.686 | BF4: =SQRT((BB4)^2 + (BD4)^2) -> 0.22321514 | BG4: =BF4^2 -> 0.049825 | BH4: 0.7 | BI4: =(BE4-BH4)^2 -> 0.000196 | BJ4: Both Sides Convered after 1st 100 ns
A5: Y91 | B5: 611 | C5: 2.01 | E5: W50 | F5: 348 | G5: 1.28 | J5: 5 ns | K5: Heavy Chain | L5: G54 | M5: G353 | N5: A353 | O5: 11.25 | P5: 0.308 | Q5: 11.538 | R5: 0.104 | S5: =O5-Q5 -> -0.288 | T5: =SQRT((P5)^2 + (R5)^2) -> 0.3250846 | U5: =T5^2 -> 0.10568 | V5: -1.28 | W5: =(S5-V5)^2 -> 0.984064 | X5: Converged | AA5: 20 ns | AB5: Heavy Chain | AC5: W47 | AD5: W345 | AE5: A345 | AF5: -33.622 | AG5: 0.414 | AH5: -37.578 | AI5: 0.168 | AJ5: =AF5-AH5 -> 3.956 | AK5: =SQRT((AG5)^2 + (AI5)^2) -> 0.44678854 | AL5: =AK5^2 -> 0.19962 | AM5: 1.19 | AN5: =(AJ5-AM5)^2 -> 7.650756 | AO5: Complex averaged for run 213&214. Run 215 has nan. Antibody converged after 2nd 100 ns | AV5: 100 ns | AW5: Heavy Chain | AX5: W47 | AY5: W345 | AZ5: A345 | BA5: -33.622 | BB5: 0.414 | BC5: -37.578 | BD5: 0.168 | BE5: =BA5-BC5 -> 3.956 | BF5: =SQRT((BB5)^2 + (BD5)^2) -> 0.44678854 | BG5: =BF5^2 -> 0.19962 | BH5: 1.19 | BI5: =(BE5-BH5)^2 -> 7.650756 | BJ5: Complex averaged for run 213&214. Run 215 has nan. Antibody converged after 2nd 100 ns
A6: F97 | B6: 613 | C6: 0.85 | E6: G54 | F6: 353 | G6: -1.28 | J6: 5 ns | K6: Heavy Chain | L6: G55 | M6: G354 | N6: A354 | O6: 14.666 | P6: 0.143 | Q6: 13.262 | R6: 0.112 | S6: =O6-Q6 -> 1.404 | T6: =SQRT((P6)^2 + (R6)^2) -> 0.18163975 | U6: =T6^2 -> 0.032993 | V6: 1.26 | W6: =(S6-V6)^2 -> 0.020736 | X6: Converged | AA6: 100 ns | AB6: Heavy Chain | AC6: W50 | AD6: W348 | AE6: A348 | AF6: -40.415 | AG6: 0.307 | AH6: -41.499 | AI6: 0.234 | AJ6: =AF6-AH6 -> 1.084 | AK6: =SQRT((AG6)^2 + (AI6)^2) -> 0.38601166 | AL6: =AK6^2 -> 0.149005 | AM6: 1.28 | AN6: =(AJ6-AM6)^2 -> 0.038416 | AO6: Complex averaged for run213,214, and 215. Antibody converged after 1st 100 ns | AV6: 100 ns | AW6: Heavy Chain | AX6: W50 | AY6: W348 | AZ6: A348 | BA6: -40.415 | BB6: 0.307 | BC6: -41.499 | BD6: 0.234 | BE6: =BA6-BC6 -> 1.084 | BF6: =SQRT((BB6)^2 + (BD6)^2) -> 0.38601166 | BG6: =BF6^2 -> 0.149005 | BH6: 1.28 | BI6: =(BE6-BH6)^2 -> 0.038416 | BJ6: Complex averaged for run213,214, and 215. Antibody converged after 1st 100 ns
A7: V3 | B7: 525 | C7: -0.78 | E7: G55 | F7: 354 | G7: 1.26 | J7: 5 ns | K7: Heavy Chain | L7: V57 | M7: V356 | N7: A356 | O7: -5.458 | P7: 0.167 | Q7: -5.831 | R7: 0.041 | S7: =O7-Q7 -> 0.373 | T7: =SQRT((P7)^2 + (R7)^2) -> 0.1719593 | U7: =T7^2 -> 0.02957 | V7: 1.35 | W7: =(S7-V7)^2 -> 0.954529 | X7: Converged | AA7: 20 ns | AB7: Heavy Chain | AC7: G54 | AD7: G353 | AE7: A353 | AF7: 12.587 | AG7: 0.145 | AH7: 11.454 | AI7: 0.09 | AJ7: =AF7-AH7 -> 1.133 | AK7: =SQRT((AG7)^2 + (AI7)^2) -> 0.17066048 | AL7: =AK7^2 -> 0.029125 | AM7: -1.28 | AN7: =(AJ7-AM7)^2 -> 5.822569 | AO7: Both Sides Convered after 1st 20 ns | AV7: 100 ns | AW7: Heavy Chain | AX7: G54 | AY7: G353 | AZ7: A353 | BA7: 12.144 | BB7: 0.205 | BC7: 11.46 | BD7: 0.08 | BE7: =BA7-BC7 -> 0.684 | BF7: =SQRT((BB7)^2 + (BD7)^2) -> 0.22005681 | BG7: =BF7^2 -> 0.048425 | BH7: -1.28 | BI7: =(BE7-BH7)^2 -> 3.857296 | BJ7: Both Sides Convered after 1st 100 ns
E8: V57 | F8: 356 | G8: 1.35 | J8: 5 ns | K8: Heavy Chain | L8: N58 | M8: N357 | N8: A357 | O8: 70.745 | P8: 0.434 | Q8: 70.07 | R8: 0.04 | S8: =O8-Q8 -> 0.675 | T8: =SQRT((P8)^2 + (R8)^2) -> 0.43583942 | U8: =T8^2 -> 0.189956 | V8: 1.76 | W8: =(S8-V8)^2 -> 1.177225 | X8: Converged | AA8: 20 ns | AB8: Heavy Chain | AC8: G55 | AD8: G354 | AE8: A354 | AF8: 15.213 | AG8: 0.249 | AH8: 13.408 | AI8: 0.07 | AJ8: =AF8-AH8 -> 1.805 | AK8: =SQRT((AG8)^2 + (AI8)^2) -> 0.25865228 | AL8: =AK8^2 -> 0.066901 | AM8: 1.26 | AN8: =(AJ8-AM8)^2 -> 0.297025 | AO8: Both Sides Convered after 1st 20 ns | AV8: 100 ns | AW8: Heavy Chain | AX8: G55 | AY8: G354 | AZ8: A354 | BA8: 14.171 | BB8: 0.232 | BC8: 13.475 | BD8: 0.1 | BE8: =BA8-BC8 -> 0.696 | BF8: =SQRT((BB8)^2 + (BD8)^2) -> 0.25263412 | BG8: =BF8^2 -> 0.063824 | BH8: 1.26 | BI8: =(BE8-BH8)^2 -> 0.318096 | BJ8: Both Sides Convered after 1st 100 ns
E9: N58 | F9: 357 | G9: 1.76 | J9: 5 ns | K9: Heavy Chain | L9: Q64 | M9: Q363 | N9: A363 | O9: 46.478 | P9: 0.284 | Q9: 46.074 | R9: 0.06 | S9: =O9-Q9 -> 0.404 | T9: =SQRT((P9)^2 + (R9)^2) -> 0.29026884 | U9: =T9^2 -> 0.084256 | V9: -0.35 | W9: =(S9-V9)^2 -> 0.568516 | X9: Converged | AA9: 20 ns | AB9: Heavy Chain | AC9: V57 | AD9: V356 | AE9: A356 | AF9: -5.405 | AG9: 0.225 | AH9: -6.15 | AI9: 0.091 | AJ9: =AF9-AH9 -> 0.745 | AK9: =SQRT((AG9)^2 + (AI9)^2) -> 0.24270558 | AL9: =AK9^2 -> 0.058906 | AM9: 1.35 | AN9: =(AJ9-AM9)^2 -> 0.366025 | AO9: Both Sides Convered after 1st 20 ns | AV9: 100 ns | AW9: Heavy Chain | AX9: V57 | AY9: V356 | AZ9: A356 | BA9: -5.207 | BB9: 0.113 | BC9: -6.311 | BD9: 0.048 | BE9: =BA9-BC9 -> 1.104 | BF9: =SQRT((BB9)^2 + (BD9)^2) -> 0.12277215 | BG9: =BF9^2 -> 0.015073 | BH9: 1.35 | BI9: =(BE9-BH9)^2 -> 0.060516 | BJ9: Both Sides Convered after 1st 100 ns
E10: Y59 | F10: 358 | G10: 0.54 | J10: 5 ns | K10: Heavy Chain | L10: M69 | M10: M368 | N10: A368 | O10: -2.585 | P10: 0.118 | Q10: -2.673 | R10: 0.21 | S10: =O10-Q10 -> 0.088 | T10: =SQRT((P10)^2 + (R10)^2) -> 0.24088171 | U10: =T10^2 -> 0.058024 | V10: 0.52 | W10: =(S10-V10)^2 -> 0.186624 | X10: Converged | AA10: 20 ns | AB10: Heavy Chain | AC10: N58 | AD10: N357 | AE10: A357 | AF10: 69.421 | AG10: 0.413 | AH10: 70.144 | AI10: 0.026 | AJ10: =AF10-AH10 -> -0.723 | AK10: =SQRT((AG10)^2 + (AI10)^2) -> 0.41381759 | AL10: =AK10^2 -> 0.171245 | AM10: 1.76 | AN10: =(AJ10-AM10)^2 -> 6.165289 | AO10: Complex converged after 2nd 20 ns, Antibody after 1st 20 ns | AV10: 100 ns | AW10: Heavy Chain | AX10: N58 | AY10: N357 | AZ10: A357 | BA10: 69.168 | BB10: 0.277 | BC10: 70.207 | BD10: 0.029 | BE10: =BA10-BC10 -> -1.039 | BF10: =SQRT((BB10)^2 + (BD10)^2) -> 0.27851391 | BG10: =BF10^2 -> 0.07757 | BH10: 1.76 | BI10: =(BE10-BH10)^2 -> 7.834401 | BJ10: Both Sides Convered after 1st 100 ns
B11: Shown highlighted as below | E11: Q64 | F11: 363 | G11: -0.35 | J11: 5 ns | K11: Heavy Chain | L11: V73 | M11: V372 | N11: A372 | O11: -4.817 | P11: 0.202 | Q11: -5.074 | R11: 0.074 | S11: =O11-Q11 -> 0.257 | T11: =SQRT((P11)^2 + (R11)^2) -> 0.21512787 | U11: =T11^2 -> 0.04628 | V11: 1.08 | W11: =(S11-V11)^2 -> 0.677329 | X11: Converged | AA11: 20 ns | AB11: Heavy Chain | AC11: Y59 | AD11: Y358 | AE11: A358 | AF11: -6.807 | AG11: 0.339 | AH11: -6.854 | AI11: 0.277 | AJ11: =AF11-AH11 -> 0.047 | AK11: =SQRT((AG11)^2 + (AI11)^2) -> 0.43777848 | AL11: =AK11^2 -> 0.19165 | AM11: 0.54 | AN11: =(AJ11-AM11)^2 -> 0.243049 | AO11: Both Sides Convered after 1st 20 ns | AV11: 100 ns | AW11: Heavy Chain | AX11: Y59 | AY11: Y358 | AZ11: A358 | BA11: -5.674 | BB11: 0.216 | BC11: -7.025 | BD11: 0.203 | BE11: =BA11-BC11 -> 1.351 | BF11: =SQRT((BB11)^2 + (BD11)^2) -> 0.29642031 | BG11: =BF11^2 -> 0.087865 | BH11: 0.54 | BI11: =(BE11-BH11)^2 -> 0.657721 | BJ11: Both Sides Convered after 1st 100 ns
A12: Glycan Contact Residues | E12: M69 | F12: 368 | G12: 0.52 | J12: 5 ns | K12: Heavy Chain | L12: Y74 | M12: Y373 | N12: A373 | O12: -8.272 | P12: 0.206 | Q12: -8.335 | R12: 0.154 | S12: =O12-Q12 -> 0.063 | T12: =SQRT((P12)^2 + (R12)^2) -> 0.25720031 | U12: =T12^2 -> 0.066152 | V12: -0.21 | W12: =(S12-V12)^2 -> 0.074529 | X12: Converged | AA12: 20 ns | AB12: Heavy Chain | AC12: Q64 | AD12: Q363 | AE12: A363 | AF12: 46.38 | AG12: 0.126 | AH12: 45.868 | AI12: 0.08 | AJ12: =AF12-AH12 -> 0.512 | AK12: =SQRT((AG12)^2 + (AI12)^2) -> 0.14925147 | AL12: =AK12^2 -> 0.022276 | AM12: -0.35 | AN12: =(AJ12-AM12)^2 -> 0.743044 | AO12: Both Sides Convered after 1st 20 ns | AV12: 100 ns | AW12: Heavy Chain | AX12: Q64 | AY12: Q363 | AZ12: A363 | BA12: 46.331 | BB12: 0.168 | BC12: 46.075 | BD12: 0.048 | BE12: =BA12-BC12 -> 0.256 | BF12: =SQRT((BB12)^2 + (BD12)^2) -> 0.17472264 | BG12: =BF12^2 -> 0.030528 | BH12: -0.35 | BI12: =(BE12-BH12)^2 -> 0.367236 | BJ12: Both Sides Convered after 1st 100 ns
E13: V73 | F13: 372 | G13: 1.08 | U13: SUM | W13: SUM | AA13: 20 ns | AB13: Heavy Chain | AC13: M69 | AD13: M368 | AE13: A368 | AF13: -2.515 | AG13: 0.131 | AH13: -2.371 | AI13: 0.103 | AJ13: =AF13-AH13 -> -0.144 | AK13: =SQRT((AG13)^2 + (AI13)^2) -> 0.16664333 | AL13: =AK13^2 -> 0.02777 | AM13: 0.52 | AN13: =(AJ13-AM13)^2 -> 0.440896 | AO13: Both Sides Convered after 1st 20 ns | AV13: 100 ns | AW13: Heavy Chain | AX13: M69 | AY13: M368 | AZ13: A368 | BA13: -2.576 | BB13: 0.053 | BC13: -2.559 | BD13: 0.074 | BE13: =BA13-BC13 -> -0.017 | BF13: =SQRT((BB13)^2 + (BD13)^2) -> 0.091021975 | BG13: =BF13^2 -> 0.008285 | BH13: 0.52 | BI13: =(BE13-BH13)^2 -> 0.288369 | BJ13: Both Sides Convered after 1st 100 ns
E14: Y100 | F14: 402 | G14: 1.42 | U14: =SUM(U3:U12) -> 0.881154 | W14: =SUM(W3:W12) -> 4.826144 | AA14: 20 ns | AB14: Heavy Chain | AC14: V73 | AD14: V372 | AE14: A372 | AF14: -4.275 | AG14: 0.292 | AH14: -4.675 | AI14: 0.09 | AJ14: =AF14-AH14 -> 0.4 | AK14: =SQRT((AG14)^2 + (AI14)^2) -> 0.30555523 | AL14: =AK14^2 -> 0.093364 | AM14: 1.08 | AN14: =(AJ14-AM14)^2 -> 0.4624 | AO14: Both Sides Convered after 1st 20 ns | AV14: 100 ns | AW14: Heavy Chain | AX14: V73 | AY14: V372 | AZ14: A372 | BA14: -4.014 | BB14: 0.203 | BC14: -4.47 | BD14: 0.137 | BE14: =BA14-BC14 -> 0.456 | BF14: =SQRT((BB14)^2 + (BD14)^2) -> 0.24490406 | BG14: =BF14^2 -> 0.059978 | BH14: 1.08 | BI14: =(BE14-BH14)^2 -> 0.389376 | BJ14: Both Sides Convered after 1st 100 ns
E15: Y74 | F15: Y373 | G15: -0.21 | AA15: 100 ns | AB15: Heavy Chain | AC15: Y100 | AD15: Y402 | AE15: A402 | AF15: -8.488 | AG15: 0.107 | AH15: -9.178 | AI15: 0.229 | AJ15: =AF15-AH15 -> 0.69 | AK15: =SQRT((AG15)^2 + (AI15)^2) -> 0.25276471 | AL15: =AK15^2 -> 0.06389 | AM15: 1.42 | AN15: =(AJ15-AM15)^2 -> 0.5329 | AO15: Both Sides Convered after 1st 100 ns | AV15: 100 ns | AW15: Heavy Chain | AX15: Y100 | AY15: Y402 | AZ15: A402 | BA15: -8.488 | BB15: 0.107 | BC15: -9.178 | BD15: 0.229 | BE15: =BA15-BC15 -> 0.69 | BF15: =SQRT((BB15)^2 + (BD15)^2) -> 0.25276471 | BG15: =BF15^2 -> 0.06389 | BH15: 1.42 | BI15: =(BE15-BH15)^2 -> 0.5329 | BJ15: Both Sides Convered after 1st 100 ns
E16: N100A | F16: 403 | G16: 1.11 | V16: RMSE | W16: =SQRT(W14/10) -> 0.69470454 | AA16: 20 ns | AB16: Heavy Chain | AC16: Y74 | AD16: Y373 | AE16: A373 | AF16: -8.137 | AG16: 0.107 | AH16: -8.55 | AI16: 0.09192388 | AJ16: =AF16-AH16 -> 0.413 | AK16: =SQRT((AG16)^2 + (AI16)^2) -> 0.14106381 | AL16: =AK16^2 -> 0.019899 | AM16: -0.21 | AN16: =(AJ16-AM16)^2 -> 0.388129 | AO16: Both Sides Convered after 1st 20 ns | AV16: 100 ns | AW16: Heavy Chain | AX16: Y74 | AY16: Y373 | AZ16: A373 | BA16: -8.32 | BB16: 0.0813941 | BC16: -8.639 | BD16: 0.02441311 | BE16: =BA16-BC16 -> 0.319 | BF16: =SQRT((BB16)^2 + (BD16)^2) -> 0.084976464 | BG16: =BF16^2 -> 0.0072209995 | BH16: -0.21 | BI16: =(BE16-BH16)^2 -> 0.279841 | BJ16: Both Sides Convered after 1st 100 ns
E17: W100B | F17: 404 | G17: 4.45 | V17: Uncertainty | W17: =SQRT(U14/10) -> 0.29684238 | AA17: 20 ns | AB17: Heavy Chain | AC17: N100A | AD17: N403 | AE17: A403 | AF17: 71.344 | AG17: 0.199 | AH17: 69.975 | AI17: 0.268 | AJ17: =AF17-AH17 -> 1.369 | AK17: =SQRT((AG17)^2 + (AI17)^2) -> 0.33380383 | AL17: =AK17^2 -> 0.111425 | AM17: 1.11 | AN17: =(AJ17-AM17)^2 -> 0.067081 | AO17: Both Sides Convered after 1st 20 ns | AV17: 100 ns | AW17: Heavy Chain | AX17: N100A | AY17: N403 | AZ17: A403 | BA17: 71.228 | BB17: 0.373 | BC17: 69.39 | BD17: 0.107 | BE17: =BA17-BC17 -> 1.838 | BF17: =SQRT((BB17)^2 + (BD17)^2) -> 0.38804381 | BG17: =BF17^2 -> 0.150578 | BH17: 1.11 | BI17: =(BE17-BH17)^2 -> 0.529984 | BJ17: Both Sides Convered after 1st 100 ns
AA18: 100 ns | AB18: Heavy Chain | AC18: W100B | AD18: W404 | AE18: A404 | AF18: -35.639 | AG18: 0.385 | AH18: -40.425 | AI18: 0.127 | AJ18: =AF18-AH18 -> 4.786 | AK18: =SQRT((AG18)^2 + (AI18)^2) -> 0.40540597 | AL18: =AK18^2 -> 0.164354 | AM18: 4.45 | AN18: =(AJ18-AM18)^2 -> 0.112896 | AO18: Complex converged after 2nd 100 ns, Antibody after 1st 100 ns | AV18: 100 ns | AW18: Heavy Chain | AX18: W100B | AY18: W404 | AZ18: A404 | BA18: -35.639 | BB18: 0.385 | BC18: -40.425 | BD18: 0.127 | BE18: =BA18-BC18 -> 4.786 | BF18: =SQRT((BB18)^2 + (BD18)^2) -> 0.40540597 | BG18: =BF18^2 -> 0.164354 | BH18: 4.45 | BI18: =(BE18-BH18)^2 -> 0.112896 | BJ18: Complex converged after 2nd 100 ns, Antibody after 1st 100 ns
J19: 5 ns - Light Chain | AL19: SUM | AN19: SUM | BG19: SUM | BI19: SUM
J20: Time | K20: Chain | L20: Residue Number | M20: Mutation | N20: Alanine | O20: DG-Complex | P20: Uncertainty-Complex | Q20: DG-Antibody | R20: Uncertainty-Antibody | S20: DDG | T20: Uncertainty | U20: Uncertainty^2 | V20: Database | W20: Squared Error | X20: Convergence Status | AL20: =SUM(AL3:AL18) -> 1.495503 | AN20: =SUM(AN3:AN18) -> 24.4772 | BG20: =SUM(BG3:BG18) -> 1.217251 | BI20: =SUM(BI3:BI18) -> 23.081216
J21: 5 ns | K21: Light Chain | L21: Q27 | M21: Q549 | N21: A549 | O21: 46.745 | P21: 0.205 | Q21: 46.756 | R21: 0.157 | S21: =O21-Q21 -> -0.011 | T21: =SQRT((P21)^2 + (R21)^2) -> 0.25821309 | U21: =T21^2 -> 0.066674 | V21: -0.24 | W21: =(S21-V21)^2 -> 0.052441 | X21: Converged
J22: 5 ns | K22: Light Chain | L22: Y28 | M22: Y550 | N22: A550 | O22: -8.67 | P22: 0.206 | Q22: -9.001 | R22: 0.171 | S22: =O22-Q22 -> 0.331 | T22: =SQRT((P22)^2 + (R22)^2) -> 0.26772561 | U22: =T22^2 -> 0.071677 | V22: 0.97 | W22: =(S22-V22)^2 -> 0.408321 | X22: Converged | AM22: RMSE | AN22: =SQRT(AN20/16) -> 1.2368609 | BH22: RMSE | BI22: =SQRT(BI20/16) -> 1.2010729
J23: 5 ns | K23: Light Chain | L23: S30 | M23: S552 | N23: A552 | O23: -8.53 | P23: 0.094 | Q23: -8.322 | R23: 0.18 | S23: =O23-Q23 -> -0.208 | T23: =SQRT((P23)^2 + (R23)^2) -> 0.20306649 | U23: =T23^2 -> 0.041236 | V23: -0.15 | W23: =(S23-V23)^2 -> 0.003364 | X23: Converged | AM23: Uncertainty | AN23: =SQRT(AL20/16) -> 0.3057269 | BH23: Uncertainty | BI23: =SQRT(BG20/16) -> 0.27582275
J24: 5 ns | K24: Light Chain | L24: V3 | M24: V525 | N24: A525 | O24: -11.339 | P24: 0.282 | Q24: -10.26 | R24: 0.121 | S24: =O24-Q24 -> -1.079 | T24: =SQRT((P24)^2 + (R24)^2) -> 0.30686316 | U24: =T24^2 -> 0.094165 | V24: -0.78 | W24: =(S24-V24)^2 -> 0.089401 | X24: Converged | AA24: 20 ns - Light Chain | AV24: 100 ns - Light Chain
U25: SUM | W25: SUM | AA25: Time | AB25: Chain | AC25: Residue Number | AD25: Mutation | AE25: Alanine | AF25: DG-Complex | AG25: Uncertainty-Complex | AH25: DG-Antibody | AI25: Uncertainty-Antibody | AJ25: DDG | AK25: Uncertainty | AL25: Uncertainty^2 | AM25: Database | AN25: Squared Error | AO25: Convergence Status | AV25: Time | AW25: Chain | AX25: Residue Number | AY25: Mutation | AZ25: Alanine | BA25: DG-Complex | BB25: Uncertainty-Complex | BC25: DG-Antibody | BD25: Uncertainty-Antibody | BE25: DDG | BF25: Uncertainty | BG25: Uncertainty^2 | BH25: Database | BI25: Squared Error | BJ25: Convergence Status
U26: =SUM(U21:U24) -> 0.273752 | W26: =SUM(W21:W24) -> 0.553527 | AA26: 20 ns | AB26: Light Chain | AC26: Q27 | AD26: Q549 | AE26: A549 | AF26: 46.597 | AG26: 0.138 | AH26: 46.381 | AI26: 0.076 | AJ26: =AF26-AH26 -> 0.216 | AK26: =SQRT((AG26)^2 + (AI26)^2) -> 0.15754364 | AL26: =AK26^2 -> 0.02482 | AM26: -0.24 | AN26: =(AJ26-AM26)^2 -> 0.207936 | AO26: Both Sides Convered after 1st 20 ns | AV26: 100 ns | AW26: Light Chain | AX26: Q27 | AY26: Q549 | AZ26: A549 | BA26: 46.501 | BB26: 0.09 | BC26: 46.497 | BD26: 0.082 | BE26: =BA26-BC26 -> 0.004 | BF26: =SQRT((BB26)^2 + (BD26)^2) -> 0.12175385 | BG26: =BF26^2 -> 0.014824 | BH26: -0.24 | BI26: =(BE26-BH26)^2 -> 0.059536 | BJ26: Conplex and antibody converged after 1st 100 ns
AA27: 100 ns | AB27: Light Chain | AC27: Y28 | AD27: Y550 | AE27: A550 | AF27: -8.877 | AG27: 0.029 | AH27: -8.448 | AI27: 0.115 | AJ27: =AF27-AH27 -> -0.429 | AK27: =SQRT((AG27)^2 + (AI27)^2) -> 0.11860017 | AL27: =AK27^2 -> 0.014066 | AM27: 0.97 | AN27: =(AJ27-AM27)^2 -> 1.957201 | AO27: Conplex and antibody converged after 1st 100 ns | AV27: 100 ns | AW27: Light Chain | AX27: Y28 | AY27: Y550 | AZ27: A550 | BA27: -8.877 | BB27: 0.029 | BC27: -8.448 | BD27: 0.115 | BE27: =BA27-BC27 -> -0.429 | BF27: =SQRT((BB27)^2 + (BD27)^2) -> 0.11860017 | BG27: =BF27^2 -> 0.014066 | BH27: 0.97 | BI27: =(BE27-BH27)^2 -> 1.957201 | BJ27: Conplex and antibody converged after 1st 100 ns
V28: RMSE | W28: =SQRT(W26/4) -> 0.37199698 | AA28: 100 ns | AB28: Light Chain | AC28: S30 | AD28: S552 | AE28: A552 | AF28: -8.381 | AG28: 0.062 | AH28: -8.229 | AI28: 0.073 | AJ28: =AF28-AH28 -> -0.152 | AK28: =SQRT((AG28)^2 + (AI28)^2) -> 0.09577578 | AL28: =AK28^2 -> 0.009173 | AM28: -0.15 | AN28: =(AJ28-AM28)^2 -> 4e-06 | AO28: Conplex and antibody converged after 1st 100 ns | AV28: 100 ns | AW28: Light Chain | AX28: S30 | AY28: S552 | AZ28: A552 | BA28: -8.381 | BB28: 0.062 | BC28: -8.229 | BD28: 0.073 | BE28: =BA28-BC28 -> -0.152 | BF28: =SQRT((BB28)^2 + (BD28)^2) -> 0.09577578 | BG28: =BF28^2 -> 0.009173 | BH28: -0.15 | BI28: =(BE28-BH28)^2 -> 4e-06 | BJ28: Conplex and antibody converged after 1st 100 ns
V29: Uncertainty | W29: =SQRT(U26/4) -> 0.26160657 | AA29: 100 ns | AB29: Light Chain | AC29: Y91 | AD29: Y611 | AE29: A611 | AF29: -5.702 | AG29: 0.241 | AH29: -7.963 | AI29: 0.096 | AJ29: =AF29-AH29 -> 2.261 | AK29: =SQRT((AG29)^2 + (AI29)^2) -> 0.25941665 | AL29: =AK29^2 -> 0.067297 | AM29: 2.01 | AN29: =(AJ29-AM29)^2 -> 0.063001 | AO29: Conplex and antibody converged after 1st 100 ns | AV29: 100 ns | AW29: Light Chain | AX29: Y91 | AY29: Y611 | AZ29: A611 | BA29: -5.702 | BB29: 0.241 | BC29: -7.963 | BD29: 0.096 | BE29: =BA29-BC29 -> 2.261 | BF29: =SQRT((BB29)^2 + (BD29)^2) -> 0.25941665 | BG29: =BF29^2 -> 0.067297 | BH29: 2.01 | BI29: =(BE29-BH29)^2 -> 0.063001 | BJ29: Conplex and antibody converged after 1st 100 ns
J30: 5 ns - All | AA30: 20 ns | AB30: Light Chain | AC30: F97 | AD30: F613 | AE30: A613 | AF30: -23.72 | AG30: 0.117 | AH30: -23.589 | AI30: 0.141 | AJ30: =AF30-AH30 -> -0.131 | AK30: =SQRT((AG30)^2 + (AI30)^2) -> 0.18322118 | AL30: =AK30^2 -> 0.03357 | AM30: 0.85 | AN30: =(AJ30-AM30)^2 -> 0.962361 | AO30: Complex converged after 2nd 20 ns, antibody converged after 1st 20 ns | AV30: 100 ns | AW30: Light Chain | AX30: F97 | AY30: F613 | AZ30: A613 | BA30: -23.943 | BB30: 0.187 | BC30: -24.111 | BD30: 0.116 | BE30: =BA30-BC30 -> 0.168 | BF30: =SQRT((BB30)^2 + (BD30)^2) -> 0.22005681 | BG30: =BF30^2 -> 0.048425 | BH30: 0.85 | BI30: =(BE30-BH30)^2 -> 0.465124 | BJ30: Conplex and antibody converged after 1st 100 ns
J31: Time | K31: Chain | L31: Residue Number | M31: Mutation | N31: Alanine | O31: DG-Complex | P31: Uncertainty-Complex | Q31: DG-Antibody | R31: Uncertainty-Antibody | S31: DDG | T31: Uncertainty | U31: Uncertainty^2 | V31: Database | W31: Squared Error | AA31: 20 ns | AB31: Light Chain | AC31: V3 | AD31: V525 | AE31: A525 | AF31: -11.115 | AG31: 0.283 | AH31: -10.105 | AI31: 0.123 | AJ31: =AF31-AH31 -> -1.01 | AK31: =SQRT((AG31)^2 + (AI31)^2) -> 0.30857414 | AL31: =AK31^2 -> 0.095218 | AM31: -0.78 | AN31: =(AJ31-AM31)^2 -> 0.0529 | AO31: Both Sides Convered after 1st 20 ns | AV31: 100 ns | AW31: Light Chain | AX31: V3 | AY31: V525 | AZ31: A525 | BA31: -10.511 | BB31: 0.139 | BC31: -10.164 | BD31: 0.04 | BE31: =BA31-BC31 -> -0.347 | BF31: =SQRT((BB31)^2 + (BD31)^2) -> 0.14464093 | BG31: =BF31^2 -> 0.020921 | BH31: -0.78 | BI31: =(BE31-BH31)^2 -> 0.187489 | BJ31: Conplex and antibody converged after 1st 100 ns
J32: 5 ns | K32: Heavy Chain | L32: I30 | M32: I328 | N32: A328 | O32: -13.536 | P32: 0.457 | Q32: -13.862 | R32: 0.163 | S32: =O32-Q32 -> 0.326 | T32: =SQRT((P32)^2 + (R32)^2) -> 0.48519893 | U32: =T32^2 -> 0.235418 | V32: -0.01 | W32: =(S32-V32)^2 -> 0.112896 | AL32: SUM | AN32: SUM | BG32: SUM | BI32: SUM
J33: 5 ns | K33: Heavy Chain | L33: T33 | M33: T331 | N33: A331 | O33: 11.72 | P33: 0.115 | Q33: 11.284 | R33: 0.14 | S33: =O33-Q33 -> 0.436 | T33: =SQRT((P33)^2 + (R33)^2) -> 0.18117671 | U33: =T33^2 -> 0.032825 | V33: 0.7 | W33: =(S33-V33)^2 -> 0.069696 | AL33: =SUM(AL26:AL31) -> 0.244144 | AN33: =SUM(AN26:AN31) -> 3.243403 | BG33: =SUM(BG26:BG31) -> 0.174706 | BI33: =SUM(BI26:BI31) -> 2.732355
J34: 5 ns | K34: Heavy Chain | L34: G54 | M34: G353 | N34: A353 | O34: 11.25 | P34: 0.308 | Q34: 11.538 | R34: 0.104 | S34: =O34-Q34 -> -0.288 | T34: =SQRT((P34)^2 + (R34)^2) -> 0.3250846 | U34: =T34^2 -> 0.10568 | V34: -1.28 | W34: =(S34-V34)^2 -> 0.984064
J35: 5 ns | K35: Heavy Chain | L35: G55 | M35: G354 | N35: A354 | O35: 14.666 | P35: 0.143 | Q35: 13.262 | R35: 0.112 | S35: =O35-Q35 -> 1.404 | T35: =SQRT((P35)^2 + (R35)^2) -> 0.18163975 | U35: =T35^2 -> 0.032993 | V35: 1.26 | W35: =(S35-V35)^2 -> 0.020736 | AM35: RMSE | AN35: =SQRT(AN33/6) -> 0.73523273 | BH35: RMSE | BI35: =SQRT(BI33/6) -> 0.67482776
J36: 5 ns | K36: Heavy Chain | L36: V57 | M36: V356 | N36: A356 | O36: -5.458 | P36: 0.167 | Q36: -5.831 | R36: 0.041 | S36: =O36-Q36 -> 0.373 | T36: =SQRT((P36)^2 + (R36)^2) -> 0.1719593 | U36: =T36^2 -> 0.02957 | V36: 1.35 | W36: =(S36-V36)^2 -> 0.954529 | AM36: Uncertainty | AN36: =SQRT(AL33/6) -> 0.20171928 | BH36: Uncertainty | BI36: =SQRT(BG33/6) -> 0.170639
J37: 5 ns | K37: Heavy Chain | L37: N58 | M37: N357 | N37: A357 | O37: 70.745 | P37: 0.434 | Q37: 70.07 | R37: 0.04 | S37: =O37-Q37 -> 0.675 | T37: =SQRT((P37)^2 + (R37)^2) -> 0.43583942 | U37: =T37^2 -> 0.189956 | V37: 1.76 | W37: =(S37-V37)^2 -> 1.177225 | AV37: 100 ns - All
J38: 5 ns | K38: Heavy Chain | L38: Q64 | M38: Q363 | N38: A363 | O38: 46.478 | P38: 0.284 | Q38: 46.074 | R38: 0.06 | S38: =O38-Q38 -> 0.404 | T38: =SQRT((P38)^2 + (R38)^2) -> 0.29026884 | U38: =T38^2 -> 0.084256 | V38: -0.35 | W38: =(S38-V38)^2 -> 0.568516 | AA38: 20 ns -All | AV38: Time | AW38: Chain | AX38: Residue Number | AY38: Mutation | AZ38: Alanine | BA38: DG-Complex | BB38: Uncertainty-Complex | BC38: DG-Antibody | BD38: Uncertainty-Antibody | BE38: DDG | BF38: Uncertainty | BG38: Uncertainty^2 | BH38: Database | BI38: Squared Error
J39: 5 ns | K39: Heavy Chain | L39: M69 | M39: M368 | N39: A368 | O39: -2.585 | P39: 0.118 | Q39: -2.673 | R39: 0.21 | S39: =O39-Q39 -> 0.088 | T39: =SQRT((P39)^2 + (R39)^2) -> 0.24088171 | U39: =T39^2 -> 0.058024 | V39: 0.52 | W39: =(S39-V39)^2 -> 0.186624 | AA39: Time | AB39: Chain | AC39: Residue Number | AD39: Mutation | AE39: Alanine | AF39: DG-Complex | AG39: Uncertainty-Complex | AH39: DG-Antibody | AI39: Uncertainty-Antibody | AJ39: DDG | AK39: Uncertainty | AL39: Uncertainty^2 | AM39: Database | AN39: Squared Error | AV39: 100 ns | AW39: Heavy Chain | AX39: I30 | AY39: I328 | AZ39: A328 | BA39: -12.769 | BB39: 0.187 | BC39: -13.163 | BD39: 0.079 | BE39: =BA39-BC39 -> 0.394 | BF39: =SQRT((BB39)^2 + (BD39)^2) -> 0.20300246 | BG39: =BF39^2 -> 0.04121 | BH39: -0.01 | BI39: =(BE39-BH39)^2 -> 0.163216
J40: 5 ns | K40: Heavy Chain | L40: V73 | M40: V372 | N40: A372 | O40: -4.817 | P40: 0.202 | Q40: -5.074 | R40: 0.074 | S40: =O40-Q40 -> 0.257 | T40: =SQRT((P40)^2 + (R40)^2) -> 0.21512787 | U40: =T40^2 -> 0.04628 | V40: 1.08 | W40: =(S40-V40)^2 -> 0.677329 | AA40: 20 ns | AB40: Heavy Chain | AC40: I30 | AD40: I328 | AE40: A328 | AF40: -12.409 | AG40: 0.209 | AH40: -13.033 | AI40: 0.202 | AJ40: =AF40-AH40 -> 0.624 | AK40: =SQRT((AG40)^2 + (AI40)^2) -> 0.29066304 | AL40: =AK40^2 -> 0.084485 | AM40: -0.01 | AN40: =(AJ40-AM40)^2 -> 0.401956 | AV40: 100 ns | AW40: Heavy Chain | AX40: T33 | AY40: T331 | AZ40: A331 | BA40: 11.429 | BB40: 0.177 | BC40: 10.743 | BD40: 0.136 | BE40: =BA40-BC40 -> 0.686 | BF40: =SQRT((BB40)^2 + (BD40)^2) -> 0.22321514 | BG40: =BF40^2 -> 0.049825 | BH40: 0.7 | BI40: =(BE40-BH40)^2 -> 0.000196
...

Sheet Truncated VRC03
A1: VRC03 Light Chain | B1: VRC03 Homology Model Light Chain | C1: ∆∆G (Kcal/mol) | E1: VRC03 Heavy Chain | F1: VRC03 Homology Model Heavy Chain | G1: ∆∆G (Kcal/mol) | J1: 5 ns - Heavy Chain | AA1: 20 ns - Heavy Chain | AV1: 100 ns - Heavy Chain
A2: Q27 | B2: 558 | C2: -0.22 | E2: W47 | F2: W345 | G2: 1.48 | J2: Time | K2: Chain | L2: Residue Number | M2: Mutation | N2: Alanine | O2: DG-Complex | P2: Uncertainty-Complex | Q2: DG-Antibody | R2: Uncertainty-Antibody | S2: DDG | T2: Uncertainty | U2: Uncertainty^2 | V2: Database | W2: Squared Error | X2: Convergence Status | AA2: Time | AB2: Chain | AC2: Residue Number | AD2: Mutation | AE2: Alanine | AF2: DG-Complex | AG2: Uncertainty-Complex | AH2: DG-Antibody | AI2: Uncertainty-Antibody | AJ2: DDG | AK2: Uncertainty | AL2: Uncertainty^2 | AM2: Database | AN2: Squared Error | AO2: Convergence Status | AV2: Time | AW2: Chain | AX2: Residue Number | AY2: Mutation | AZ2: Alanine | BA2: DG-Complex | BB2: Uncertainty-Complex | BC2: DG-Antibody | BD2: Uncertainty-Antibody | BE2: DDG | BF2: Uncertainty | BG2: Uncertainty^2 | BH2: Database | BI2: Squared Error | BJ2: Convergence Status
A3: N30 | B3: 561 | C3: 0.2 | E3: W50 | F3: W348 | G3: 1.33 | J3: 5 ns | K3: Heavy Chain | L3: L54 | M3: L352 | N3: A352 | O3: 4.809 | P3: 0.269 | Q3: 6.426 | R3: 0.042 | S3: =O3-Q3 -> -1.617 | T3: =SQRT((P3)^2 + (R3)^2) -> 0.27225907 | U3: =T3^2 -> 0.074125 | V3: 0.05 | W3: =(S3-V3)^2 -> 2.778889 | X3: Converged | AA3: 100 ns | AB3: Heavy Chain | AC3: W47 | AD3: W345 | AE3: A345 | AF3: -32.768 | AG3: 0.253 | AH3: -37.601 | AI3: 0.17 | AJ3: =AF3-AH3 -> 4.833 | AK3: =SQRT((AG3)^2 + (AI3)^2) -> 0.30480978 | AL3: =AK3^2 -> 0.092909 | AM3: 1.48 | AN3: =(AJ3-AM3)^2 -> 11.242609 | AO3: Complex converged after 2nd 100 ns. Antibody converged after 1st 100 ns. | AV3: 100 ns | AW3: Heavy Chain | AX3: W47 | AY3: W345 | AZ3: A345 | BA3: -32.768 | BB3: 0.253 | BC3: -37.601 | BD3: 0.17 | BE3: =BA3-BC3 -> 4.833 | BF3: =SQRT((BB3)^2 + (BD3)^2) -> 0.30480978 | BG3: =BF3^2 -> 0.092909 | BH3: 1.48 | BI3: =(BE3-BH3)^2 -> 11.242609 | BJ3: Complex converged after 2nd 100 ns. Antibody converged after 1st 100 ns.
A4: F90 | B4: 621 | C4: -0.87 | E4: L54 | F4: L352 | G4: 0.05 | J4: 5 ns | K4: Heavy Chain | L4: G56 | M4: G354 | N4: A354 | O4: 14.904 | P4: 0.217 | Q4: 12.847 | R4: 0.212 | S4: =O4-Q4 -> 2.057 | T4: =SQRT((P4)^2 + (R4)^2) -> 0.30336941 | U4: =T4^2 -> 0.092033 | V4: 0.35 | W4: =(S4-V4)^2 -> 2.913849 | X4: Converged | AA4: 100 ns | AB4: Heavy Chain | AC4: W50 | AD4: W348 | AE4: A348 | AF4: -40.854 | AG4: 0.308 | AH4: -42.294 | AI4: 0.098 | AJ4: =AF4-AH4 -> 1.44 | AK4: =SQRT((AG4)^2 + (AI4)^2) -> 0.3232151 | AL4: =AK4^2 -> 0.104468 | AM4: 1.33 | AN4: =(AJ4-AM4)^2 -> 0.0121 | AO4: Complex converged after 2nd 100 ns. Antibody converged after 1st 100 ns. | AV4: 100 ns | AW4: Heavy Chain | AX4: W50 | AY4: W348 | AZ4: A348 | BA4: -40.854 | BB4: 0.308 | BC4: -42.294 | BD4: 0.098 | BE4: =BA4-BC4 -> 1.44 | BF4: =SQRT((BB4)^2 + (BD4)^2) -> 0.3232151 | BG4: =BF4^2 -> 0.104468 | BH4: 1.33 | BI4: =(BE4-BH4)^2 -> 0.0121 | BJ4: Complex converged after 2nd 100 ns. Antibody converged after 1st 100 ns.
A5: F92 | B5: 623 | C5: 0.83 | E5: W55 | F5: W353 | G5: 0.76 | J5: 5 ns | K5: Heavy Chain | L5: V58 | M5: V356 | N5: A356 | O5: -5.401 | P5: 0.265 | Q5: -5.794 | R5: 0.081 | S5: =O5-Q5 -> 0.393 | T5: =SQRT((P5)^2 + (R5)^2) -> 0.27710287 | U5: =T5^2 -> 0.076786 | V5: 1.25 | W5: =(S5-V5)^2 -> 0.734449 | X5: Converged | AA5: 20 ns | AB5: Heavy Chain | AC5: L54 | AD5: L352 | AE5: A352 | AF5: 5.507 | AG5: 0.385 | AH5: 6.383 | AI5: 0.164 | AJ5: =AF5-AH5 -> -0.876 | AK5: =SQRT((AG5)^2 + (AI5)^2) -> 0.41847461 | AL5: =AK5^2 -> 0.175121 | AM5: 0.05 | AN5: =(AJ5-AM5)^2 -> 0.857476 | AO5: Both Sides Convered after 1st 20 ns | AV5: 100 ns | AW5: Heavy Chain | AX5: L54 | AY5: L352 | AZ5: A352 | BA5: 5.885 | BB5: 0.308 | BC5: 6.095 | BD5: 0.059 | BE5: =BA5-BC5 -> -0.21 | BF5: =SQRT((BB5)^2 + (BD5)^2) -> 0.31360006 | BG5: =BF5^2 -> 0.098345 | BH5: 0.05 | BI5: =(BE5-BH5)^2 -> 0.0676 | BJ5: Complex and antibody converged after 1st 100 ns
E6: G56 | F6: G354 | G6: 0.35 | J6: 5 ns | K6: Heavy Chain | L6: S59 | M6: S357 | N6: A357 | O6: -5.068 | P6: 0.162 | Q6: -6.867 | R6: 0.034 | S6: =O6-Q6 -> 1.799 | T6: =SQRT((P6)^2 + (R6)^2) -> 0.16552945 | U6: =T6^2 -> 0.0274 | V6: 1.15 | W6: =(S6-V6)^2 -> 0.421201 | X6: Converged | AA6: 100 ns | AB6: Heavy Chain | AC6: W55 | AD6: W353 | AE6: A353 | AF6: -39.873 | AG6: 0.339 | AH6: -42.363 | AI6: 0.047 | AJ6: =AF6-AH6 -> 2.49 | AK6: =SQRT((AG6)^2 + (AI6)^2) -> 0.3422426 | AL6: =AK6^2 -> 0.11713 | AM6: 0.76 | AN6: =(AJ6-AM6)^2 -> 2.9929 | AO6: Complex and antibody converged after 1st 100 ns | AV6: 100 ns | AW6: Heavy Chain | AX6: W55 | AY6: W353 | AZ6: A353 | BA6: -39.873 | BB6: 0.339 | BC6: -42.363 | BD6: 0.047 | BE6: =BA6-BC6 -> 2.49 | BF6: =SQRT((BB6)^2 + (BD6)^2) -> 0.3422426 | BG6: =BF6^2 -> 0.11713 | BH6: 0.76 | BI6: =(BE6-BH6)^2 -> 2.9929 | BJ6: Complex and antibody converged after 1st 100 ns
E7: V58 | F7: V356 | G7: 1.25 | J7: 5 ns | K7: Heavy Chain | L7: Y60 | M7: Y358 | N7: A358 | O7: -4.972 | P7: 0.233 | Q7: -5.353 | R7: 0.226 | S7: =O7-Q7 -> 0.381 | T7: =SQRT((P7)^2 + (R7)^2) -> 0.32459975 | U7: =T7^2 -> 0.105365 | V7: 0.86 | W7: =(S7-V7)^2 -> 0.229441 | X7: Converged | AA7: 20 ns | AB7: Heavy Chain | AC7: G56 | AD7: G354 | AE7: A354 | AF7: 15.722 | AG7: 0.171 | AH7: 13.2 | AI7: 0.107 | AJ7: =AF7-AH7 -> 2.522 | AK7: =SQRT((AG7)^2 + (AI7)^2) -> 0.20171762 | AL7: =AK7^2 -> 0.04069 | AM7: 0.35 | AN7: =(AJ7-AM7)^2 -> 4.717584 | AO7: Both Sides Convered after 1st 20 ns | AV7: 100 ns | AW7: Heavy Chain | AX7: G56 | AY7: G354 | AZ7: A354 | BA7: 15.317 | BB7: 0.129 | BC7: 13.378 | BD7: 0.045 | BE7: =BA7-BC7 -> 1.939 | BF7: =SQRT((BB7)^2 + (BD7)^2) -> 0.13662357 | BG7: =BF7^2 -> 0.018666 | BH7: 0.35 | BI7: =(BE7-BH7)^2 -> 2.524921 | BJ7: Complex and antibody converged after 1st 100 ns
E8: S59 | F8: S357 | G8: 1.15 | J8: 5 ns | K8: Heavy Chain | L8: Q63 | M8: Q361 | N8: A361 | O8: 47.298 | P8: 0.318 | Q8: 46.334 | R8: 0.027 | S8: =O8-Q8 -> 0.964 | T8: =SQRT((P8)^2 + (R8)^2) -> 0.31914417 | U8: =T8^2 -> 0.101853 | V8: 1.11 | W8: =(S8-V8)^2 -> 0.021316 | X8: Converged | AA8: 20 ns | AB8: Heavy Chain | AC8: V58 | AD8: V356 | AE8: A356 | AF8: -5.315 | AG8: 0.23 | AH8: -5.753 | AI8: 0.077 | AJ8: =AF8-AH8 -> 0.438 | AK8: =SQRT((AG8)^2 + (AI8)^2) -> 0.2425469 | AL8: =AK8^2 -> 0.058829 | AM8: 1.25 | AN8: =(AJ8-AM8)^2 -> 0.659344 | AO8: Both Sides Convered after 1st 20 ns | AV8: 100 ns | AW8: Heavy Chain | AX8: V58 | AY8: V356 | AZ8: A356 | BA8: -5.338 | BB8: 0.11 | BC8: -5.745 | BD8: 0.029 | BE8: =BA8-BC8 -> 0.407 | BF8: =SQRT((BB8)^2 + (BD8)^2) -> 0.11375852 | BG8: =BF8^2 -> 0.012941 | BH8: 1.25 | BI8: =(BE8-BH8)^2 -> 0.710649 | BJ8: Complex and antibody converged after 1st 100 ns
E9: Y60 | F9: Y358 | G9: 0.86 | J9: 5 ns | K9: Heavy Chain | L9: Q65 | M9: Q363 | N9: A363 | O9: 47.186 | P9: 0.235 | Q9: 45.956 | R9: 0.065 | S9: =O9-Q9 -> 1.23 | T9: =SQRT((P9)^2 + (R9)^2) -> 0.24382371 | U9: =T9^2 -> 0.05945 | V9: 0.55 | W9: =(S9-V9)^2 -> 0.4624 | X9: Converged | AA9: 20 ns | AB9: Heavy Chain | AC9: S59 | AD9: S357 | AE9: A357 | AF9: -5.461 | AG9: 0.069 | AH9: -6.91 | AI9: 0.045 | AJ9: =AF9-AH9 -> 1.449 | AK9: =SQRT((AG9)^2 + (AI9)^2) -> 0.082377181 | AL9: =AK9^2 -> 0.006786 | AM9: 1.15 | AN9: =(AJ9-AM9)^2 -> 0.089401 | AO9: Both Sides Convered after 1st 20 ns | AV9: 100 ns | AW9: Heavy Chain | AX9: S59 | AY9: S357 | AZ9: A357 | BA9: -5.589 | BB9: 0.156 | BC9: -7.125 | BD9: 0.09 | BE9: =BA9-BC9 -> 1.536 | BF9: =SQRT((BB9)^2 + (BD9)^2) -> 0.18009997 | BG9: =BF9^2 -> 0.032436 | BH9: 1.15 | BI9: =(BE9-BH9)^2 -> 0.148996 | BJ9: Complex and antibody converged after 1st 100 ns
E10: Q63 | F10: Q361 | G10: 1.11 | J10: 5 ns | K10: Heavy Chain | L10: Q76 | M10: Q374 | N10: A374 | O10: 46.653 | P10: 0.089 | Q10: 46.852 | R10: 0.143 | S10: =O10-Q10 -> -0.199 | T10: =SQRT((P10)^2 + (R10)^2) -> 0.16843396 | U10: =T10^2 -> 0.02837 | V10: 0.09 | W10: =(S10-V10)^2 -> 0.083521 | X10: Converged | AA10: 20 ns | AB10: Heavy Chain | AC10: Y60 | AD10: Y358 | AE10: A358 | AF10: -5.761 | AG10: 0.127 | AH10: -5.878 | AI10: 0.345 | AJ10: =AF10-AH10 -> 0.117 | AK10: =SQRT((AG10)^2 + (AI10)^2) -> 0.36763297 | AL10: =AK10^2 -> 0.135154 | AM10: 0.86 | AN10: =(AJ10-AM10)^2 -> 0.552049 | AO10: Both Sides Convered after 1st 20 ns | AV10: 100 ns | AW10: Heavy Chain | AX10: Y60 | AY10: Y358 | AZ10: A358 | BA10: -6.017 | BB10: 0.253 | BC10: -6.242 | BD10: 0.157 | BE10: =BA10-BC10 -> 0.225 | BF10: =SQRT((BB10)^2 + (BD10)^2) -> 0.29775493 | BG10: =BF10^2 -> 0.088658 | BH10: 0.86 | BI10: =(BE10-BH10)^2 -> 0.403225 | BJ10: Complex and antibody converged after 1st 100 ns
E11: Q65 | F11: Q363 | G11: 0.55 | J11: 5 ns | K11: Heavy Chain | L11: Y111 | M11: Y409 | N11: A409 | O11: -8.356 | P11: 0.153 | Q11: -7.906 | R11: 0.333 | S11: =O11-Q11 -> -0.45 | T11: =SQRT((P11)^2 + (R11)^2) -> 0.36646692 | U11: =T11^2 -> 0.134298 | V11: 0.83 | W11: =(S11-V11)^2 -> 1.6384 | X11: Converged | AA11: 20 ns | AB11: Heavy Chain | AC11: Q63 | AD11: Q361 | AE11: A361 | AF11: 47.467 | AG11: 0.094 | AH11: 46.307 | AI11: 0.044 | AJ11: =AF11-AH11 -> 1.16 | AK11: =SQRT((AG11)^2 + (AI11)^2) -> 0.10378825 | AL11: =AK11^2 -> 0.010772 | AM11: 1.11 | AN11: =(AJ11-AM11)^2 -> 0.0025 | AO11: Both Sides Convered after 1st 20 ns | AV11: 100 ns | AW11: Heavy Chain | AX11: Q63 | AY11: Q361 | AZ11: A361 | BA11: 46.832 | BB11: 0.127 | BC11: 46.287 | BD11: 0.031 | BE11: =BA11-BC11 -> 0.545 | BF11: =SQRT((BB11)^2 + (BD11)^2) -> 0.13072873 | BG11: =BF11^2 -> 0.01709 | BH11: 1.11 | BI11: =(BE11-BH11)^2 -> 0.319225 | BJ11: Complex and antibody converged after 1st 100 ns
E12: Q76 | F12: Q374 | G12: 0.09 | J12: 5 ns | K12: Heavy Chain | L12: F115 | M12: F413 | N12: A413 | O12: -16.396 | P12: 0.312 | Q12: -20.651 | R12: 0.212 | S12: =O12-Q12 -> 4.255 | T12: =SQRT((P12)^2 + (R12)^2) -> 0.37721082 | U12: =T12^2 -> 0.142288 | V12: 1.07 | W12: =(S12-V12)^2 -> 10.144225 | X12: Converged | AA12: 20 ns | AB12: Heavy Chain | AC12: Q65 | AD12: Q363 | AE12: A363 | AF12: 46.467 | AG12: 0.204 | AH12: 45.91 | AI12: 0.047 | AJ12: =AF12-AH12 -> 0.557 | AK12: =SQRT((AG12)^2 + (AI12)^2) -> 0.20934421 | AL12: =AK12^2 -> 0.043825 | AM12: 0.55 | AN12: =(AJ12-AM12)^2 -> 4.9e-05 | AO12: Both Sides Convered after 1st 20 ns | AV12: 100 ns | AW12: Heavy Chain | AX12: Q65 | AY12: Q363 | AZ12: A363 | BA12: 46.542 | BB12: 0.132 | BC12: 45.903 | BD12: 0.066 | BE12: =BA12-BC12 -> 0.639 | BF12: =SQRT((BB12)^2 + (BD12)^2) -> 0.14758049 | BG12: =BF12^2 -> 0.02178 | BH12: 0.55 | BI12: =(BE12-BH12)^2 -> 0.007921 | BJ12: Complex and antibody converged after 1st 100 ns
E13: Y111 | F13: Y409 | G13: 0.83 | U13: SUM | W13: SUM | AA13: 20 ns | AB13: Heavy Chain | AC13: Q76 | AD13: Q374 | AE13: A374 | AF13: 46.451 | AG13: 0.059 | AH13: 46.647 | AI13: 0.035 | AJ13: =AF13-AH13 -> -0.196 | AK13: =SQRT((AG13)^2 + (AI13)^2) -> 0.068600292 | AL13: =AK13^2 -> 0.004706 | AM13: 0.09 | AN13: =(AJ13-AM13)^2 -> 0.081796 | AO13: Both Sides Convered after 1st 20 ns | AV13: 100 ns | AW13: Heavy Chain | AX13: Q76 | AY13: Q374 | AZ13: A374 | BA13: 46.751 | BB13: 0.057 | BC13: 46.564 | BD13: 0.028 | BE13: =BA13-BC13 -> 0.187 | BF13: =SQRT((BB13)^2 + (BD13)^2) -> 0.063505905 | BG13: =BF13^2 -> 0.004033 | BH13: 0.09 | BI13: =(BE13-BH13)^2 -> 0.009409 | BJ13: Complex and antibody converged after 1st 100 ns
B14: Shown highlighted as below | E14: F115 | F14: F413 | G14: 1.07 | U14: =SUM(U3:U12) -> 0.841968 | W14: =SUM(W3:W12) -> 19.427691 | AA14: 20 ns | AB14: Heavy Chain | AC14: Y111 | AD14: Y409 | AE14: A409 | AF14: -8.458 | AG14: 0.1 | AH14: -8.694 | AI14: 0.131 | AJ14: =AF14-AH14 -> 0.236 | AK14: =SQRT((AG14)^2 + (AI14)^2) -> 0.16480595 | AL14: =AK14^2 -> 0.027161 | AM14: 0.83 | AN14: =(AJ14-AM14)^2 -> 0.352836 | AO14: Both Sides Convered after 1st 20 ns | AV14: 100 ns | AW14: Heavy Chain | AX14: Y111 | AY14: Y409 | AZ14: A409 | BA14: -8.738 | BB14: 0.091 | BC14: -8.655 | BD14: 0.035 | BE14: =BA14-BC14 -> -0.083 | BF14: =SQRT((BB14)^2 + (BD14)^2) -> 0.097498718 | BG14: =BF14^2 -> 0.009506 | BH14: 0.83 | BI14: =(BE14-BH14)^2 -> 0.833569 | BJ14: Complex and antibody converged after 1st 100 ns
A15: Glycan Contact Residues | AA15: 100 ns | AB15: Heavy Chain | AC15: F115 | AD15: F413 | AE15: A413 | AF15: -19.974 | AG15: 0.986 | AH15: -22.345 | AI15: 0.19 | AJ15: =AF15-AH15 -> 2.371 | AK15: =SQRT((AG15)^2 + (AI15)^2) -> 1.0041394 | AL15: =AK15^2 -> 1.008296 | AM15: 1.07 | AN15: =(AJ15-AM15)^2 -> 1.692601 | AO15: Averaged 2nd and 3rd 100 ns for Complex , Antibody converged after 1st 100 ns | AV15: 100 ns | AW15: Heavy Chain | AX15: F115 | AY15: F413 | AZ15: A413 | BA15: -19.974 | BB15: 0.986 | BC15: -22.345 | BD15: 0.19 | BE15: =BA15-BC15 -> 2.371 | BF15: =SQRT((BB15)^2 + (BD15)^2) -> 1.0041394 | BG15: =BF15^2 -> 1.008296 | BH15: 1.07 | BI15: =(BE15-BH15)^2 -> 1.692601 | BJ15: Averaged 2nd and 3rd 100 ns for Complex , Antibody converged after 1st 100 ns
V16: RMSE | W16: =SQRT(W14/10) -> 1.3938325 | AL16: SUM | AN16: SUM | BG16: SUM | BI16: SUM
V17: Uncertainty | W17: =SQRT(U14/10) -> 0.29016685 | AL17: =SUM(AL3:AL15) -> 1.825847 | AN17: =SUM(AN3:AN15) -> 23.253245 | BG17: =SUM(BG3:BG15) -> 1.626258 | BI17: =SUM(BI3:BI15) -> 20.965725
AM19: RMSE | AN19: =SQRT(AN17/13) -> 1.3374271 | BH19: RMSE | BI19: =SQRT(BI17/13) -> 1.2699402
J20: 5 ns - Light Chain | AM20: Uncertainty | AN20: =SQRT(AL17/13) -> 0.37476629 | BH20: Uncertainty | BI20: =SQRT(BG17/13) -> 0.35369022
J21: Time | K21: Chain | L21: Residue Number | M21: Mutation | N21: Alanine | O21: DG-Complex | P21: Uncertainty-Complex | Q21: DG-Antibody | R21: Uncertainty-Antibody | S21: DDG | T21: Uncertainty | U21: Uncertainty^2 | V21: Database | W21: Squared Error | X21: Convergence Status
J22: 5 ns | K22: Light Chain | L22: Q27 | M22: Q558 | N22: A558 | O22: 46.568 | P22: 0.137 | Q22: 46.351 | R22: 0.06 | S22: =O22-Q22 -> 0.217 | T22: =SQRT((P22)^2 + (R22)^2) -> 0.1495627 | U22: =T22^2 -> 0.022369 | V22: -0.22 | W22: =(S22-V22)^2 -> 0.190969 | X22: Converged
J23: 5 ns | K23: Light Chain | L23: N30 | M23: N561 | N23: A561 | O23: 68.072 | P23: 0.094 | Q23: 68.706 | R23: 0.115 | S23: =O23-Q23 -> -0.634 | T23: =SQRT((P23)^2 + (R23)^2) -> 0.14852946 | U23: =T23^2 -> 0.022061 | V23: 0.2 | W23: =(S23-V23)^2 -> 0.695556 | X23: Converged | AA23: 20 ns - Light Chain
J24: 5 ns | K24: Light Chain | L24: F90 | M24: F621 | N24: A621 | O24: -22.6 | P24: 0.183 | Q24: -24.513 | R24: 0.149 | S24: =O24-Q24 -> 1.913 | T24: =SQRT((P24)^2 + (R24)^2) -> 0.23598729 | U24: =T24^2 -> 0.05569 | V24: -0.87 | W24: =(S24-V24)^2 -> 7.745089 | X24: Converged | AA24: Time | AB24: Chain | AC24: Residue Number | AD24: Mutation | AE24: Alanine | AF24: DG-Complex | AG24: Uncertainty-Complex | AH24: DG-Antibody | AI24: Uncertainty-Antibody | AJ24: DDG | AK24: Uncertainty | AL24: Uncertainty^2 | AM24: Database | AN24: Squared Error | AO24: Convergence Status
J25: 5 ns | K25: Light Chain | L25: F92 | M25: F623 | N25: A623 | O25: -22.948 | P25: 0.151 | Q25: -24.226 | R25: 0.223 | S25: =O25-Q25 -> 1.278 | T25: =SQRT((P25)^2 + (R25)^2) -> 0.26931394 | U25: =T25^2 -> 0.07253 | V25: 0.83 | W25: =(S25-V25)^2 -> 0.200704 | X25: Converged | AA25: 20 ns | AB25: Light Chain | AC25: Q27 | AD25: Q558 | AE25: A558 | AF25: 46.144 | AG25: 0.061 | AH25: 46.199 | AI25: 0.114 | AJ25: =AF25-AH25 -> -0.055 | AK25: =SQRT((AG25)^2 + (AI25)^2) -> 0.12929424 | AL25: =AK25^2 -> 0.016717 | AM25: -0.22 | AN25: =(AJ25-AM25)^2 -> 0.027225 | AO25: Both Sides Convered after 1st 20 ns
U26: SUM | W26: SUM | AA26: 20 ns | AB26: Light Chain | AC26: N30 | AD26: N561 | AE26: A561 | AF26: 68.542 | AG26: 0.056 | AH26: 68.394 | AI26: 0.093 | AJ26: =AF26-AH26 -> 0.148 | AK26: =SQRT((AG26)^2 + (AI26)^2) -> 0.10855874 | AL26: =AK26^2 -> 0.011785 | AM26: 0.2 | AN26: =(AJ26-AM26)^2 -> 0.002704 | AO26: Both Sides Convered after 1st 20 ns | AV26: 100 ns - Light Chain
U27: =SUM(U22:U25) -> 0.17265 | W27: =SUM(W22:W25) -> 8.832318 | AA27: 100 ns | AB27: Light Chain | AC27: F90 | AD27: F621 | AE27: A621 | AF27: -23.031 | AG27: 0.143 | AH27: -24.692 | AI27: 0.067 | AJ27: =AF27-AH27 -> 1.661 | AK27: =SQRT((AG27)^2 + (AI27)^2) -> 0.1579177 | AL27: =AK27^2 -> 0.024938 | AM27: -0.87 | AN27: =(AJ27-AM27)^2 -> 6.405961 | AO27: Both Sides Convered after 1st 100 ns | AV27: Time | AW27: Chain | AX27: Residue Number | AY27: Mutation | AZ27: Alanine | BA27: DG-Complex | BB27: Uncertainty-Complex | BC27: DG-Antibody | BD27: Uncertainty-Antibody | BE27: DDG | BF27: Uncertainty | BG27: Uncertainty^2 | BH27: Database | BI27: Squared Error | BJ27: Convergence Status
AA28: 100 ns | AB28: Light Chain | AC28: F92 | AD28: F623 | AE28: A623 | AF28: -22.321 | AG28: 0.113 | AH28: -24.714 | AI28: 0.24 | AJ28: =AF28-AH28 -> 2.393 | AK28: =SQRT((AG28)^2 + (AI28)^2) -> 0.26527156 | AL28: =AK28^2 -> 0.070369 | AM28: 0.83 | AN28: =(AJ28-AM28)^2 -> 2.442969 | AO28: Both Sides Convered after 1st 100 ns | AV28: 100 ns | AW28: Light Chain | AX28: Q27 | AY28: Q558 | AZ28: A558 | BA28: 46.196 | BB28: 0.067 | BC28: 46.013 | BD28: 0.064 | BE28: =BA28-BC28 -> 0.183 | BF28: =SQRT((BB28)^2 + (BD28)^2) -> 0.092655275 | BG28: =BF28^2 -> 0.008585 | BH28: -0.22 | BI28: =(BE28-BH28)^2 -> 0.162409 | BJ28: Both Sides Convered after 1st 100 ns
V29: RMSE | W29: =SQRT(W27/4) -> 1.4859608 | AL29: SUM | AN29: SUM | AV29: 100 ns | AW29: Light Chain | AX29: N30 | AY29: N561 | AZ29: A561 | BA29: 68.663 | BB29: 0.067 | BC29: 68.444 | BD29: 0.058 | BE29: =BA29-BC29 -> 0.219 | BF29: =SQRT((BB29)^2 + (BD29)^2) -> 0.088617154 | BG29: =BF29^2 -> 0.007853 | BH29: 0.2 | BI29: =(BE29-BH29)^2 -> 0.000361 | BJ29: Both Sides Convered after 1st 100 ns
V30: Uncertainty | W30: =SQRT(U27/4) -> 0.20775587 | AL30: =SUM(AL25:AL28) -> 0.123809 | AN30: =SUM(AN25:AN28) -> 8.878859 | AV30: 100 ns | AW30: Light Chain | AX30: F90 | AY30: F621 | AZ30: A621 | BA30: -23.031 | BB30: 0.143 | BC30: -24.692 | BD30: 0.067 | BE30: =BA30-BC30 -> 1.661 | BF30: =SQRT((BB30)^2 + (BD30)^2) -> 0.1579177 | BG30: =BF30^2 -> 0.024938 | BH30: -0.87 | BI30: =(BE30-BH30)^2 -> 6.405961 | BJ30: Both Sides Convered after 1st 100 ns
AV31: 100 ns | AW31: Light Chain | AX31: F92 | AY31: F623 | AZ31: A623 | BA31: -22.321 | BB31: 0.113 | BC31: -24.714 | BD31: 0.24 | BE31: =BA31-BC31 -> 2.393 | BF31: =SQRT((BB31)^2 + (BD31)^2) -> 0.26527156 | BG31: =BF31^2 -> 0.070369 | BH31: 0.83 | BI31: =(BE31-BH31)^2 -> 2.442969 | BJ31: Both Sides Convered after 1st 100 ns
AM32: RMSE | AN32: =SQRT(AN30/4) -> 1.4898707 | BG32: SUM | BI32: SUM
J33: 5 ns - All | AM33: Uncertainty | AN33: =SQRT(AL30/4) -> 0.17593252 | BG33: =SUM(BG28:BG31) -> 0.111745 | BI33: =SUM(BI28:BI31) -> 9.0117
J34: Time | K34: Chain | L34: Residue Number | M34: Mutation | N34: Alanine | O34: DG-Complex | P34: Uncertainty-Complex | Q34: DG-Antibody | R34: Uncertainty-Antibody | S34: DDG | T34: Uncertainty | U34: Uncertainty^2 | V34: Database | W34: Squared Error
J35: 5 ns | K35: Heavy Chain | L35: L54 | M35: L352 | N35: A352 | O35: 4.809 | P35: 0.269 | Q35: 6.426 | R35: 0.042 | S35: =O35-Q35 -> -1.617 | T35: =SQRT((P35)^2 + (R35)^2) -> 0.27225907 | U35: =T35^2 -> 0.074125 | V35: 0.05 | W35: =(S35-V35)^2 -> 2.778889 | BH35: RMSE | BI35: =SQRT(BI33/4) -> 1.5009747
J36: 5 ns | K36: Heavy Chain | L36: G56 | M36: G354 | N36: A354 | O36: 14.904 | P36: 0.217 | Q36: 12.847 | R36: 0.212 | S36: =O36-Q36 -> 2.057 | T36: =SQRT((P36)^2 + (R36)^2) -> 0.30336941 | U36: =T36^2 -> 0.092033 | V36: 0.35 | W36: =(S36-V36)^2 -> 2.913849 | AA36: 20 ns - All | BH36: Uncertainty | BI36: =SQRT(BG33/4) -> 0.16714141
J37: 5 ns | K37: Heavy Chain | L37: V58 | M37: V356 | N37: A356 | O37: -5.401 | P37: 0.265 | Q37: -5.794 | R37: 0.081 | S37: =O37-Q37 -> 0.393 | T37: =SQRT((P37)^2 + (R37)^2) -> 0.27710287 | U37: =T37^2 -> 0.076786 | V37: 1.25 | W37: =(S37-V37)^2 -> 0.734449 | AA37: Time | AB37: Chain | AC37: Residue Number | AD37: Mutation | AE37: Alanine | AF37: DG-Complex | AG37: Uncertainty-Complex | AH37: DG-Antibody | AI37: Uncertainty-Antibody | AJ37: DDG | AK37: Uncertainty | AL37: Uncertainty^2 | AM37: Database | AN37: Squared Error
J38: 5 ns | K38: Heavy Chain | L38: S59 | M38: S357 | N38: A357 | O38: -5.068 | P38: 0.162 | Q38: -6.867 | R38: 0.034 | S38: =O38-Q38 -> 1.799 | T38: =SQRT((P38)^2 + (R38)^2) -> 0.16552945 | U38: =T38^2 -> 0.0274 | V38: 1.15 | W38: =(S38-V38)^2 -> 0.421201 | AA38: 100 ns | AB38: Heavy Chain | AC38: W47 | AD38: W345 | AE38: A345 | AF38: -32.768 | AG38: 0.253 | AH38: -37.601 | AI38: 0.17 | AJ38: =AF38-AH38 -> 4.833 | AK38: =SQRT((AG38)^2 + (AI38)^2) -> 0.30480978 | AL38: =AK38^2 -> 0.092909 | AM38: 1.48 | AN38: =(AJ38-AM38)^2 -> 11.242609 | AV38: 100 ns - All
J39: 5 ns | K39: Heavy Chain | L39: Y60 | M39: Y358 | N39: A358 | O39: -4.972 | P39: 0.233 | Q39: -5.353 | R39: 0.226 | S39: =O39-Q39 -> 0.381 | T39: =SQRT((P39)^2 + (R39)^2) -> 0.32459975 | U39: =T39^2 -> 0.105365 | V39: 0.86 | W39: =(S39-V39)^2 -> 0.229441 | AA39: 100 ns | AB39: Heavy Chain | AC39: W50 | AD39: W348 | AE39: A348 | AF39: -40.854 | AG39: 0.308 | AH39: -42.294 | AI39: 0.098 | AJ39: =AF39-AH39 -> 1.44 | AK39: =SQRT((AG39)^2 + (AI39)^2) -> 0.3232151 | AL39: =AK39^2 -> 0.104468 | AM39: 1.33 | AN39: =(AJ39-AM39)^2 -> 0.0121 | AV39: Time | AW39: Chain | AX39: Residue Number | AY39: Mutation | AZ39: Alanine | BA39: DG-Complex | BB39: Uncertainty-Complex | BC39: DG-Antibody | BD39: Uncertainty-Antibody | BE39: DDG | BF39: Uncertainty | BG39: Uncertainty^2 | BH39: Database | BI39: Squared Error
J40: 5 ns | K40: Heavy Chain | L40: Q63 | M40: Q361 | N40: A361 | O40: 47.298 | P40: 0.318 | Q40: 46.334 | R40: 0.027 | S40: =O40-Q40 -> 0.964 | T40: =SQRT((P40)^2 + (R40)^2) -> 0.31914417 | U40: =T40^2 -> 0.101853 | V40: 1.11 | W40: =(S40-V40)^2 -> 0.021316 | AA40: 20 ns | AB40: Heavy Chain | AC40: L54 | AD40: L352 | AE40: A352 | AF40: 5.507 | AG40: 0.385 | AH40: 6.383 | AI40: 0.164 | AJ40: =AF40-AH40 -> -0.876 | AK40: =SQRT((AG40)^2 + (AI40)^2) -> 0.41847461 | AL40: =AK40^2 -> 0.175121 | AM40: 0.05 | AN40: =(AJ40-AM40)^2 -> 0.857476 | AV40: 100 ns | AW40: Heavy Chain | AX40: W47 | AY40: W345 | AZ40: A345 | BA40: -32.768 | BB40: 0.253 | BC40: -37.601 | BD40: 0.17 | BE40: =BA40-BC40 -> 4.833 | BF40: =SQRT((BB40)^2 + (BD40)^2) -> 0.30480978 | BG40: =BF40^2 -> 0.092909 | BH40: 1.48 | BI40: =(BE40-BH40)^2 -> 11.242609
J41: 5 ns | K41: Heavy Chain | L41: Q65 | M41: Q363 | N41: A363 | O41: 47.186 | P41: 0.235 | Q41: 45.956 | R41: 0.065 | S41: =O41-Q41 -> 1.23 | T41: =SQRT((P41)^2 + (R41)^2) -> 0.24382371 | U41: =T41^2 -> 0.05945 | V41: 0.55 | W41: =(S41-V41)^2 -> 0.4624 | AA41: 100 ns | AB41: Heavy Chain | AC41: W55 | AD41: W353 | AE41: A353 | AF41: -39.873 | AG41: 0.339 | AH41: -42.363 | AI41: 0.047 | AJ41: =AF41-AH41 -> 2.49 | AK41: =SQRT((AG41)^2 + (AI41)^2) -> 0.3422426 | AL41: =AK41^2 -> 0.11713 | AM41: 0.76 | AN41: =(AJ41-AM41)^2 -> 2.9929 | AV41: 100 ns | AW41: Heavy Chain | AX41: W50 | AY41: W348 | AZ41: A348 | BA41: -40.854 | BB41: 0.308 | BC41: -42.294 | BD41: 0.098 | BE41: =BA41-BC41 -> 1.44 | BF41: =SQRT((BB41)^2 + (BD41)^2) -> 0.3232151 | BG41: =BF41^2 -> 0.104468 | BH41: 1.33 | BI41: =(BE41-BH41)^2 -> 0.0121
...

Sheet Truncated VRC-PG04
A1: VRC-PG04 Light Chain | B1: VRC-PG04 Homology Model Light Chain | C1: ∆∆G (Kcal/mol) | D1: VRC-PG04 Heavy Chain | E1: VRC-PG04 Homology Model Heavy Chain | F1: ∆∆G (Kcal/mol) | J1: 5 ns - Heavy Chain | AA1: 20 ns - Heavy Chain | AV1: 100 ns - Heavy Chain
A2: V3 | B2: 526 | C2: -0.51 | D2: L34 | E2: 332 | F2: 0.57 | J2: Time | K2: Chain | L2: Residue Number | M2: Mutation | N2: Alanine | O2: DG-Complex | P2: Uncertainty-Complex | Q2: DG-Antibody | R2: Uncertainty-Antibody | S2: DDG | T2: Uncertainty | U2: Uncertainty^2 | V2: Database | W2: Squared Error | X2: Convergence Status | AA2: Time | AB2: Chain | AC2: Residue Number | AD2: Mutation | AE2: Alanine | AF2: DG-Complex | AG2: Uncertainty-Complex | AH2: DG-Antibody | AI2: Uncertainty-Antibody | AJ2: DDG | AK2: Uncertainty | AL2: Uncertainty^2 | AM2: Database | AN2: Squared Error | AO2: Convergence Status | AV2: Time | AW2: Chain | AX2: Residue Number | AY2: Mutation | AZ2: Alanine | BA2: DG-Complex | BB2: Uncertainty-Complex | BC2: DG-Antibody | BD2: Uncertainty-Antibody | BE2: DDG | BF2: Uncertainty | BG2: Uncertainty^2 | BH2: Database | BI2: Squared Error | BJ2: Convergence Status
A3: Y30 | B3: 551 | C3: 1.13 | D3: W47 | E3: 346 | F3: 1.07 | J3: 5 ns | K3: Heavy Chain | L3: W50 | M3: W349 | N3: A349 | O3: -37.261 | P3: 0.487 | Q3: -42.449 | R3: 0.443 | S3: =O3-Q3 -> 5.188 | T3: =SQRT((P3)^2 + (R3)^2) -> 0.65834489 | U3: =T3^2 -> 0.433418 | V3: 1.53 | W3: =(S3-V3)^2 -> 13.380964 | X3: Converged | AA3: 20 ns | AB3: Heavy Chain | AC3: L34 | AD3: L332 | AE3: A332 | AF3: 4.749 | AG3: 0.398 | AH3: 2.624 | AI3: 0.248 | AJ3: =AF3-AH3 -> 2.125 | AK3: =SQRT((AG3)^2 + (AI3)^2) -> 0.46894349 | AL3: =AK3^2 -> 0.219908 | AM3: 0.57 | AN3: =(AJ3-AM3)^2 -> 2.418025 | AO3: Both Sides Converged after 1st 20 ns | AV3: 100 ns | AW3: Heavy Chain | AX3: L34 | AY3: L332 | AZ3: A332 | BA3: 5.277 | BB3: 0.12 | BC3: 2.081 | BD3: 0.141 | BE3: 3.196 | BF3: 0.18515129 | BG3: 0.034281 | BH3: 0.57 | BI3: 6.895876 | BJ3: Both Sides Converged after 1st 100 ns
A4: G31 | B4: 552 | C4: 0.47 | D4: W50 | E4: 349 | F4: 1.53 | J4: 5 ns | K4: Heavy Chain | L4: V52B | M4: V353 | N4: A353 | O4: -3.988 | P4: 0.158 | Q4: -3.817 | R4: 0.049 | S4: =O4-Q4 -> -0.171 | T4: =SQRT((P4)^2 + (R4)^2) -> 0.1654237 | U4: =T4^2 -> 0.027365 | V4: -0.82 | W4: =(S4-V4)^2 -> 0.421201 | X4: Converged | AA4: 100 ns | AB4: Heavy Chain | AC4: W47 | AD4: W346 | AE4: A346 | AF4: -38.622 | AG4: 0.701 | AH4: -40.955 | AI4: 0.219 | AJ4: =AF4-AH4 -> 2.333 | AK4: =SQRT((AG4)^2 + (AI4)^2) -> 0.73441269 | AL4: =AK4^2 -> 0.539362 | AM4: 1.07 | AN4: =(AJ4-AM4)^2 -> 1.595169 | AO4: Average of thrid and 4th 100 ns for Complex, Antibody Converged after 1st 100 ns | AV4: 100 ns | AW4: Heavy Chain | AX4: W47 | AY4: W346 | AZ4: A346 | BA4: -38.622 | BB4: 0.701 | BC4: -40.955 | BD4: 0.219 | BE4: 2.333 | BF4: 0.73441269 | BG4: 0.539362 | BH4: 1.07 | BI4: 1.595169 | BJ4: Average of thrid and 4th 100 ns for Complex, Antibody Converged after 1st 100 ns
A5: L91 | B5: 612 | C5: 0.97 | D5: V52B | E5: 353 | F5: -0.82 | J5: 5 ns | K5: Heavy Chain | L5: T53 | M5: T354 | N5: A354 | O5: 12.399 | P5: 0.324 | Q5: 12.984 | R5: 0.038 | S5: =O5-Q5 -> -0.585 | T5: =SQRT((P5)^2 + (R5)^2) -> 0.32622078 | U5: =T5^2 -> 0.10642 | V5: -0.85 | W5: =(S5-V5)^2 -> 0.070225 | X5: Converged | AA5: 100 ns | AB5: Heavy Chain | AC5: W50 | AD5: W349 | AE5: A349 | AF5: -41.331 | AG5: 0.258 | AH5: -43.83 | AI5: 0.17 | AJ5: =AF5-AH5 -> 2.499 | AK5: =SQRT((AG5)^2 + (AI5)^2) -> 0.30897249 | AL5: =AK5^2 -> 0.095464 | AM5: 1.53 | AN5: =(AJ5-AM5)^2 -> 0.938961 | AO5: Average of 1st to third 100 ns for Complex, Antibody Converegd after 1st 100 ns | AV5: 100 ns | AW5: Heavy Chain | AX5: W50 | AY5: W349 | AZ5: A349 | BA5: -41.331 | BB5: 0.258 | BC5: -43.83 | BD5: 0.17 | BE5: 2.499 | BF5: 0.30897249 | BG5: 0.095464 | BH5: 1.53 | BI5: 0.938961 | BJ5: Average of 1st to third 100 ns for Complex, Antibody Converegd after 1st 100 ns
A6: F97 | B6: 614 | C6: 0.02 | D6: T53 | E6: 354 | F6: -0.85 | J6: 5 ns | K6: Heavy Chain | L6: G54 | M6: G355 | N6: A355 | O6: 16.52 | P6: 0.1 | Q6: 13.998 | R6: 0.055 | S6: =O6-Q6 -> 2.522 | T6: =SQRT((P6)^2 + (R6)^2) -> 0.11412712 | U6: =T6^2 -> 0.013025 | V6: 0.46 | W6: =(S6-V6)^2 -> 4.251844 | X6: Converged | AA6: 20 ns | AB6: Heavy Chain | AC6: V52B | AD6: W353 | AE6: S353 | AF6: -4.309 | AG6: 0.234 | AH6: -4.296 | AI6: 0.048 | AJ6: =AF6-AH6 -> -0.013 | AK6: =SQRT((AG6)^2 + (AI6)^2) -> 0.23887235 | AL6: =AK6^2 -> 0.05706 | AM6: -0.82 | AN6: =(AJ6-AM6)^2 -> 0.651249 | AO6: Both Sides Converged after 1st 20 ns | AV6: 100 ns | AW6: Heavy Chain | AX6: V52B | AY6: W353 | AZ6: S353 | BA6: -4.388 | BB6: 0.133 | BC6: -4.789 | BD6: 0.11 | BE6: 0.401 | BF6: 0.1725949 | BG6: 0.029789 | BH6: -0.82 | BI6: 1.490841 | BJ6: Both Sides Converged after 1st 100 ns
D7: G54 | E7: 355 | F7: 0.46 | J7: 5 ns | K7: Heavy Chain | L7: V56 | M7: V357 | N7: A357 | O7: -4.077 | P7: 0.14 | Q7: -5.017 | R7: 0.035 | S7: =O7-Q7 -> 0.94 | T7: =SQRT((P7)^2 + (R7)^2) -> 0.1443087 | U7: =T7^2 -> 0.020825 | V7: 0.99 | W7: =(S7-V7)^2 -> 0.0025 | X7: Converged | AA7: 20 ns | AB7: Heavy Chain | AC7: T53 | AD7: T354 | AE7: A354 | AF7: 12.283 | AG7: 0.18 | AH7: 12.985 | AI7: 0.034 | AJ7: =AF7-AH7 -> -0.702 | AK7: =SQRT((AG7)^2 + (AI7)^2) -> 0.18318297 | AL7: =AK7^2 -> 0.033556 | AM7: -0.85 | AN7: =(AJ7-AM7)^2 -> 0.021904 | AO7: Both Sides Converged after 1st 20 ns | AV7: 100 ns | AW7: Heavy Chain | AX7: T53 | AY7: T354 | AZ7: A354 | BA7: 12.905 | BB7: 0.277 | BC7: 12.784 | BD7: 0.171 | BE7: 0.121 | BF7: 0.32553034 | BG7: 0.10597 | BH7: -0.85 | BI7: 0.942841 | BJ7: Both Sides Converged after 1st 100 ns
D8: V56 | E8: 357 | F8: 0.99 | J8: 5 ns | K8: Heavy Chain | L8: N57 | M8: N358 | N8: A358 | O8: 71.562 | P8: 0.393 | Q8: 69.636 | R8: 0.072 | S8: =O8-Q8 -> 1.926 | T8: =SQRT((P8)^2 + (R8)^2) -> 0.39954099 | U8: =T8^2 -> 0.159633 | V8: 1.53 | W8: =(S8-V8)^2 -> 0.156816 | X8: Converged | AA8: 20 ns | AB8: Heavy Chain | AC8: G54 | AD8: G355 | AE8: A355 | AF8: 16.119 | AG8: 0.214 | AH8: 13.843 | AI8: 0.093 | AJ8: =AF8-AH8 -> 2.276 | AK8: =SQRT((AG8)^2 + (AI8)^2) -> 0.23333452 | AL8: =AK8^2 -> 0.054445 | AM8: 0.46 | AN8: =(AJ8-AM8)^2 -> 3.297856 | AO8: Both Sides Converged after 1st 20 ns | AV8: 100 ns | AW8: Heavy Chain | AX8: G54 | AY8: G355 | AZ8: A355 | BA8: 16.305 | BB8: 0.181 | BC8: 13.923 | BD8: 0.042 | BE8: 2.382 | BF8: 0.18580904 | BG8: 0.034525 | BH8: 0.46 | BI8: 3.694084 | BJ8: Both Sides Converged after 1st 100 ns
D9: N57 | E9: 358 | F9: 1.53 | J9: 5 ns | K9: Heavy Chain | L9: Y98 | M9: Y402 | N9: A402 | O9: -8.318 | P9: 0.301 | Q9: -8.648 | R9: 0.224 | S9: =O9-Q9 -> 0.33 | T9: =SQRT((P9)^2 + (R9)^2) -> 0.37520261 | U9: =T9^2 -> 0.140777 | V9: 0.47 | W9: =(S9-V9)^2 -> 0.0196 | X9: Converged | AA9: 20 ns | AB9: Heavy Chain | AC9: V56 | AD9: V357 | AE9: A357 | AF9: -4.789 | AG9: 0.093 | AH9: -4.982 | AI9: 0.019 | AJ9: =AF9-AH9 -> 0.193 | AK9: =SQRT((AG9)^2 + (AI9)^2) -> 0.09492102 | AL9: =AK9^2 -> 0.00901 | AM9: 0.99 | AN9: =(AJ9-AM9)^2 -> 0.635209 | AO9: Both Sides Converged after 1st 20 ns | AV9: 100 ns | AW9: Heavy Chain | AX9: V56 | AY9: V357 | AZ9: A357 | BA9: -4.821 | BB9: 0.153 | BC9: -5.066 | BD9: 0.04 | BE9: 0.245 | BF9: 0.15814234 | BG9: 0.025009 | BH9: 0.99 | BI9: 0.555025 | BJ9: Both Sides Converged after 1st 100 ns
D10: G59 | E10: 360 | F10: 0.06 | J10: 5 ns | K10: Heavy Chain | L10: T99 | M10: T403 | N10: A403 | O10: 10.29 | P10: 0.211 | Q10: 10.589 | R10: 0.14 | S10: =O10-Q10 -> -0.299 | T10: =SQRT((P10)^2 + (R10)^2) -> 0.25322125 | U10: =T10^2 -> 0.064121 | V10: -0.43 | W10: =(S10-V10)^2 -> 0.017161 | X10: Converged | AA10: 20 ns | AB10: Heavy Chain | AC10: N57 | AD10: N358 | AE10: A358 | AF10: 70.179 | AG10: 0.241 | AH10: 69.418 | AI10: 0.04 | AJ10: =AF10-AH10 -> 0.761 | AK10: =SQRT((AG10)^2 + (AI10)^2) -> 0.24429695 | AL10: =AK10^2 -> 0.059681 | AM10: 1.53 | AN10: =(AJ10-AM10)^2 -> 0.591361 | AO10: 2nd 20 ns for Complex, 1st 20 ns for antibody | AV10: 100 ns | AW10: Heavy Chain | AX10: N57 | AY10: N358 | AZ10: A358 | BA10: 69.619 | BB10: 0.185 | BC10: 69.455 | BD10: 0.046 | BE10: 0.164 | BF10: 0.19063316 | BG10: 0.036341 | BH10: 1.53 | BI10: 1.865956 | BJ10: Both Sides Converged after 1st 100 ns
D11: Y98 | E11: 402 | F11: 0.47 | J11: 5 ns | K11: Heavy Chain | L11: G100 | M11: G404 | N11: A404 | O11: 13.407 | P11: 0.134 | Q11: 12.718 | R11: 0.216 | S11: =O11-Q11 -> 0.689 | T11: =SQRT((P11)^2 + (R11)^2) -> 0.25418891 | U11: =T11^2 -> 0.064612 | V11: -0.27 | W11: =(S11-V11)^2 -> 0.919681 | X11: Converged | AA11: 20 ns | AB11: Heavy Chain | AC11: G59 | AD11: G360 | AE11: A360 | AF11: 11.674 | AG11: 0.111 | AH11: 12.246 | AI11: 0.173 | AJ11: =AF11-AH11 -> -0.572 | AK11: =SQRT((AG11)^2 + (AI11)^2) -> 0.20554805 | AL11: =AK11^2 -> 0.04225 | AM11: 0.06 | AN11: =(AJ11-AM11)^2 -> 0.399424 | AO11: Both Sides Converged after 1st 20 ns | AV11: 100 ns | AW11: Heavy Chain | AX11: G59 | AY11: G360 | AZ11: A360 | BA11: 11.676 | BB11: 0.052 | BC11: 12.621 | BD11: 0.145 | BE11: -0.945 | BF11: 0.1540422 | BG11: 0.023729 | BH11: 0.06 | BI11: 1.010025 | BJ11: Both Sides Converged after 1st 100 ns
D12: T99 | E12: 403 | F12: -0.43 | J12: 5 ns | K12: Heavy Chain | L12: G100A | M12: G405 | N12: A405 | O12: 10.347 | P12: 0.036 | Q12: 11.186 | R12: 0.054 | S12: =O12-Q12 -> -0.839 | T12: =SQRT((P12)^2 + (R12)^2) -> 0.064899923 | U12: =T12^2 -> 0.004212 | V12: -0.63 | W12: =(S12-V12)^2 -> 0.043681 | X12: Converged | AA12: 20 ns | AB12: Heavy Chain | AC12: Y98 | AD12: Y402 | AE12: A402 | AF12: -7.727 | AG12: 0.343 | AH12: -8.286 | AI12: 0.099 | AJ12: =AF12-AH12 -> 0.559 | AK12: =SQRT((AG12)^2 + (AI12)^2) -> 0.3570014 | AL12: =AK12^2 -> 0.12745 | AM12: 0.47 | AN12: =(AJ12-AM12)^2 -> 0.007921 | AO12: Both Sides Converged after 1st 20 ns | AV12: 100 ns | AW12: Heavy Chain | AX12: Y98 | AY12: Y402 | AZ12: A402 | BA12: -7.165 | BB12: 0.252 | BC12: -8.442 | BD12: 0.109 | BE12: 1.277 | BF12: 0.27456329 | BG12: 0.075385 | BH12: 0.47 | BI12: 0.651249 | BJ12: Both Sides Converged after 1st 100 ns
